Workbook

Sheet Master SKU Data
A1: SKU | B1: ASIN | C1: Brand | D1: Product Name | E1: Category | F1: Unit_COGS | G1: FBA_Fee | H1: Amazon_Referral_Fee_% | I1: Current_Price | J1: Buy_Box_Price | K1: Lowest_Competitor_Price | L1: Is_Buy_Box_Winner | M1: Competitor_Count | N1: Sales_Rank | O1: Available_Inventory | P1: Inbound_Inventory | Q1: Historical_Velocity_7D | R1: Days_of_Supply | S1: Storage_Type | T1: Ad_Impressions_7D | U1: Ad_Clicks_7D | V1: Ad_Spend_7D | W1: Ad_Orders_7D | X1: Ad_Sales_7D | Y1: CPC | Z1: CTR | AA1: ACOS | AB1: ROAS
A2: SKU-1000 | B2: B0100000 | C2: Aerovo | D2: Aerovo Sleeping Bag | E2: Outdoor | F2: 13.1 | G2: 4.25 | H2: 0.08 | I2: 43.55 | J2: 42.4 | K2: 44.04 | L2: =FALSE() -> FALSE | M2: 12 | N2: 40908 | O2: 724 | P2: 1236 | Q2: 227 | R2: =IF(Q2=0,999,O2/(Q2/7)) -> 22.325991 | S2: Standard | T2: 35171 | U2: 482 | V2: 694.08 | W2: 54 | X2: 2351.7 | Y2: 1.44 | Z2: =IF(T2=0,0,U2/T2) -> 0.013704472 | AA2: =IF(X2=0,0,V2/X2) -> 0.29513969 | AB2: =IF(V2=0,0,X2/V2) -> 3.3882261
A3: SKU-1001 | B3: B0100137 | C3: Aerovo | D3: Aerovo Trekking Poles | E3: Outdoor | F3: 4.44 | G3: 5.83 | H3: 0.12 | I3: 16.29 | J3: 16.29 | K3: 14.47 | L3: =TRUE() -> TRUE | M3: 9 | N3: 173496 | O3: 2434 | P3: 569 | Q3: 240 | R3: =IF(Q3=0,999,O3/(Q3/7)) -> 70.991667 | S3: Standard | T3: 59929 | U3: 695 | V3: 625.5 | W3: 159 | X3: 2590.11 | Y3: 0.9 | Z3: =IF(T3=0,0,U3/T3) -> 0.011597057 | AA3: =IF(X3=0,0,V3/X3) -> 0.24149553 | AB3: =IF(V3=0,0,X3/V3) -> 4.1408633
A4: SKU-1002 | B4: B0100274 | C4: Aerovo | D4: Aerovo Folding Chair | E4: Outdoor | F4: 22.03 | G4: 11.97 | H4: 0.08 | I4: 63.6 | J4: 63.6 | K4: 62.14 | L4: =TRUE() -> TRUE | M4: 9 | N4: 64325 | O4: 279 | P4: 1402 | Q4: 174 | R4: =IF(Q4=0,999,O4/(Q4/7)) -> 11.224138 | S4: Oversize | T4: 43004 | U4: 606 | V4: 915.06 | W4: 74 | X4: 4706.4 | Y4: 1.51 | Z4: =IF(T4=0,0,U4/T4) -> 0.014091712 | AA4: =IF(X4=0,0,V4/X4) -> 0.19442886 | AB4: =IF(V4=0,0,X4/V4) -> 5.1432693
A5: SKU-1003 | B5: B0100411 | C5: Aerovo | D5: Aerovo Camping Tent | E5: Outdoor | F5: 21.74 | G5: 7.03 | H5: 0.12 | I5: 74.39 | J5: 74.39 | K5: 72.98 | L5: =TRUE() -> TRUE | M5: 3 | N5: 168669 | O5: 4160 | P5: 1195 | Q5: 476 | R5: =IF(Q5=0,999,O5/(Q5/7)) -> 61.176471 | S5: Oversize | T5: 52850 | U5: 439 | V5: 812.15 | W5: 66 | X5: 4909.74 | Y5: 1.85 | Z5: =IF(T5=0,0,U5/T5) -> 0.0083065279 | AA5: =IF(X5=0,0,V5/X5) -> 0.16541609 | AB5: =IF(V5=0,0,X5/V5) -> 6.0453611
A6: SKU-1004 | B6: B0100548 | C6: Aerovo | D6: Aerovo Cooler Bag | E6: Outdoor | F6: 3.94 | G6: 3.49 | H6: 0.1 | I6: 17.26 | J6: 17.26 | K6: 17.02 | L6: =TRUE() -> TRUE | M6: 12 | N6: 101014 | O6: 316 | P6: 1393 | Q6: 397 | R6: =IF(Q6=0,999,O6/(Q6/7)) -> 5.5717884 | S6: Standard | T6: 94966 | U6: 513 | V6: 861.84 | W6: 136 | X6: 2347.36 | Y6: 1.68 | Z6: =IF(T6=0,0,U6/T6) -> 0.0054019333 | AA6: =IF(X6=0,0,V6/X6) -> 0.36715289 | AB6: =IF(V6=0,0,X6/V6) -> 2.723661
A7: SKU-1005 | B7: B0100685 | C7: Aerovo | D7: Aerovo Headlamp | E7: Outdoor | F7: 5.64 | G7: 5.04 | H7: 0.12 | I7: 18.91 | J7: 18.91 | K7: 18.96 | L7: =TRUE() -> TRUE | M7: 8 | N7: 28044 | O7: 628 | P7: 1104 | Q7: 312 | R7: =IF(Q7=0,999,O7/(Q7/7)) -> 14.089744 | S7: Standard | T7: 102556 | U7: 1549 | V7: 2679.77 | W7: 446 | X7: 8433.86 | Y7: 1.73 | Z7: =IF(T7=0,0,U7/T7) -> 0.015103943 | AA7: =IF(X7=0,0,V7/X7) -> 0.31773945 | AB7: =IF(V7=0,0,X7/V7) -> 3.1472328
A8: SKU-1006 | B8: B0100822 | C8: Aerovo | D8: Aerovo Utensil Organizer | E8: Kitchen | F8: 4.47 | G8: 6.95 | H8: 0.12 | I8: 11.55 | J8: 9.93 | K8: 9.95 | L8: =FALSE() -> FALSE | M8: 3 | N8: 22603 | O8: 3512 | P8: 1125 | Q8: 504 | R8: =IF(Q8=0,999,O8/(Q8/7)) -> 48.777778 | S8: Standard | T8: 22143 | U8: 159 | V8: 263.94 | W8: 88 | X8: 1016.4 | Y8: 1.66 | Z8: =IF(T8=0,0,U8/T8) -> 0.0071805988 | AA8: =IF(X8=0,0,V8/X8) -> 0.25968123 | AB8: =IF(V8=0,0,X8/V8) -> 3.8508752
A9: SKU-1007 | B9: B0100959 | C9: Aerovo | D9: Aerovo Spice Rack | E9: Kitchen | F9: 30.01 | G9: 6.1 | H9: 0.12 | I9: 84.3 | J9: 82.41 | K9: 88.43 | L9: =FALSE() -> FALSE | M9: 6 | N9: 135829 | O9: 717 | P9: 1205 | Q9: 469 | R9: =IF(Q9=0,999,O9/(Q9/7)) -> 10.701493 | S9: Standard | T9: 29364 | U9: 120 | V9: 169.2 | W9: 14 | X9: 1180.2 | Y9: 1.41 | Z9: =IF(T9=0,0,U9/T9) -> 0.0040866367 | AA9: =IF(X9=0,0,V9/X9) -> 0.14336553 | AB9: =IF(V9=0,0,X9/V9) -> 6.9751773
A10: SKU-1008 | B10: B0101096 | C10: Aerovo | D10: Aerovo Cutting Board | E10: Kitchen | F10: 30.89 | G10: 3.32 | H10: 0.1 | I10: 82.42 | J10: 82.42 | K10: 81.08 | L10: =TRUE() -> TRUE | M10: 4 | N10: 34834 | O10: 461 | P10: 198 | Q10: 591 | R10: =IF(Q10=0,999,O10/(Q10/7)) -> 5.4602369 | S10: Standard | T10: 86874 | U10: 799 | V10: 791.01 | W10: 35 | X10: 2884.7 | Y10: 0.99 | Z10: =IF(T10=0,0,U10/T10) -> 0.0091972282 | AA10: =IF(X10=0,0,V10/X10) -> 0.27420876 | AB10: =IF(V10=0,0,X10/V10) -> 3.6468566
A11: SKU-1009 | B11: B0101233 | C11: Aerovo | D11: Aerovo Knife Set | E11: Kitchen | F11: 25.36 | G11: 3.44 | H11: 0.15 | I11: 63.86 | J11: 56.85 | K11: 58.61 | L11: =FALSE() -> FALSE | M11: 11 | N11: 50012 | O11: 373 | P11: 907 | Q11: 556 | R11: =IF(Q11=0,999,O11/(Q11/7)) -> 4.6960432 | S11: Standard | T11: 106409 | U11: 1522 | V11: 1795.96 | W11: 206 | X11: 13155.16 | Y11: 1.18 | Z11: =IF(T11=0,0,U11/T11) -> 0.014303301 | AA11: =IF(X11=0,0,V11/X11) -> 0.13652133 | AB11: =IF(V11=0,0,X11/V11) -> 7.3248625
A12: SKU-1010 | B12: B0101370 | C12: Nimbus Home | D12: Nimbus Home Earbud Case | E12: Electronics Accessories | F12: 30.32 | G12: 7.17 | H12: 0.1 | I12: 76.87 | J12: 76.87 | K12: 71.59 | L12: =TRUE() -> TRUE | M12: 2 | N12: 105280 | O12: 697 | P12: 584 | Q12: 67 | R12: =IF(Q12=0,999,O12/(Q12/7)) -> 72.820896 | S12: Standard | T12: 55944 | U12: 694 | V12: 1006.3 | W12: 35 | X12: 2690.45 | Y12: 1.45 | Z12: =IF(T12=0,0,U12/T12) -> 0.012405262 | AA12: =IF(X12=0,0,V12/X12) -> 0.37402665 | AB12: =IF(V12=0,0,X12/V12) -> 2.6736063
A13: SKU-1011 | B13: B0101507 | C13: Nimbus Home | D13: Nimbus Home Power Bank | E13: Electronics Accessories | F13: 6.12 | G13: 7.36 | H13: 0.08 | I13: 22.37 | J13: 22.37 | K13: 20.42 | L13: =TRUE() -> TRUE | M13: 11 | N13: 125137 | O13: 1070 | P13: 140 | Q13: 521 | R13: =IF(Q13=0,999,O13/(Q13/7)) -> 14.3762 | S13: Standard | T13: 78492 | U13: 377 | V13: 618.28 | W13: 109 | X13: 2438.33 | Y13: 1.64 | Z13: =IF(T13=0,0,U13/T13) -> 0.0048030373 | AA13: =IF(X13=0,0,V13/X13) -> 0.25356699 | AB13: =IF(V13=0,0,X13/V13) -> 3.943731
A14: SKU-1012 | B14: B0101644 | C14: Nimbus Home | D14: Nimbus Home Monitor Light Bar | E14: Electronics Accessories | F14: 9.71 | G14: 5.79 | H14: 0.15 | I14: 29.69 | J14: 29.69 | K14: 28.7 | L14: =TRUE() -> TRUE | M14: 10 | N14: 68508 | O14: 822 | P14: 936 | Q14: 216 | R14: =IF(Q14=0,999,O14/(Q14/7)) -> 26.638889 | S14: Standard | T14: 41941 | U14: 633 | V14: 1107.75 | W14: 303 | X14: 8996.07 | Y14: 1.75 | Z14: =IF(T14=0,0,U14/T14) -> 0.01509263 | AA14: =IF(X14=0,0,V14/X14) -> 0.1231371 | AB14: =IF(V14=0,0,X14/V14) -> 8.1210291
A15: SKU-1013 | B15: B0101781 | C15: Nimbus Home | D15: Nimbus Home Monitor Light Bar | E15: Electronics Accessories | F15: 35.88 | G15: 3.33 | H15: 0.1 | I15: 89.87 | J15: 80.77 | K15: 81.16 | L15: =FALSE() -> FALSE | M15: 8 | N15: 64187 | O15: 204 | P15: 1367 | Q15: 385 | R15: =IF(Q15=0,999,O15/(Q15/7)) -> 3.7090909 | S15: Standard | T15: 107599 | U15: 1151 | V15: 2014.25 | W15: 145 | X15: 13031.15 | Y15: 1.75 | Z15: =IF(T15=0,0,U15/T15) -> 0.010697125 | AA15: =IF(X15=0,0,V15/X15) -> 0.15457193 | AB15: =IF(V15=0,0,X15/V15) -> 6.46948
A16: SKU-1014 | B16: B0101918 | C16: Nimbus Home | D16: Nimbus Home Wireless Charger Pad | E16: Electronics Accessories | F16: 11.84 | G16: 6.34 | H16: 0.1 | I16: 31.15 | J16: 31.15 | K16: 28.23 | L16: =TRUE() -> TRUE | M16: 4 | N16: 90034 | O16: 188 | P16: 189 | Q16: 215 | R16: =IF(Q16=0,999,O16/(Q16/7)) -> 6.1209302 | S16: Standard | T16: 83636 | U16: 761 | V16: 585.97 | W16: 155 | X16: 4828.25 | Y16: 0.77 | Z16: =IF(T16=0,0,U16/T16) -> 0.0090989526 | AA16: =IF(X16=0,0,V16/X16) -> 0.12136281 | AB16: =IF(V16=0,0,X16/V16) -> 8.2397563
A17: SKU-1015 | B17: B0102055 | C17: Nimbus Home | D17: Nimbus Home Wireless Charger Pad | E17: Electronics Accessories | F17: 16.29 | G17: 6.34 | H17: 0.15 | I17: 60.96 | J17: 60.96 | K17: 51.93 | L17: =TRUE() -> TRUE | M17: 8 | N17: 39223 | O17: 179 | P17: 631 | Q17: 565 | R17: =IF(Q17=0,999,O17/(Q17/7)) -> 2.2176991 | S17: Standard | T17: 48295 | U17: 715 | V17: 1101.1 | W17: 45 | X17: 2743.2 | Y17: 1.54 | Z17: =IF(T17=0,0,U17/T17) -> 0.014804845 | AA17: =IF(X17=0,0,V17/X17) -> 0.40139253 | AB17: =IF(V17=0,0,X17/V17) -> 2.4913269
A18: SKU-1016 | B18: B0102192 | C18: Nimbus Home | D18: Nimbus Home Ab Roller Wheel | E18: Fitness | F18: 7.1 | G18: 3.46 | H18: 0.15 | I18: 26.8 | J18: 25.98 | K18: 26.8 | L18: =FALSE() -> FALSE | M18: 9 | N18: 42748 | O18: 1476 | P18: 1371 | Q18: 188 | R18: =IF(Q18=0,999,O18/(Q18/7)) -> 54.957447 | S18: Standard | T18: 113754 | U18: 1456 | V18: 1048.32 | W18: 227 | X18: 6083.6 | Y18: 0.72 | Z18: =IF(T18=0,0,U18/T18) -> 0.01279955 | AA18: =IF(X18=0,0,V18/X18) -> 0.17231902 | AB18: =IF(V18=0,0,X18/V18) -> 5.8031899
A19: SKU-1017 | B19: B0102329 | C19: Nimbus Home | D19: Nimbus Home Resistance Bands Set | E19: Fitness | F19: 9.21 | G19: 5.12 | H19: 0.1 | I19: 40.59 | J19: 37.15 | K19: 37.34 | L19: =FALSE() -> FALSE | M19: 7 | N19: 58588 | O19: 119 | P19: 719 | Q19: 31 | R19: =IF(Q19=0,999,O19/(Q19/7)) -> 26.870968 | S19: Standard | T19: 84580 | U19: 854 | V19: 1169.98 | W19: 72 | X19: 2922.48 | Y19: 1.37 | Z19: =IF(T19=0,0,U19/T19) -> 0.01009695 | AA19: =IF(X19=0,0,V19/X19) -> 0.40033807 | AB19: =IF(V19=0,0,X19/V19) -> 2.4978889
A20: SKU-1018 | B20: B0102466 | C20: Nimbus Home | D20: Nimbus Home Ab Roller Wheel | E20: Fitness | F20: 20.5 | G20: 7.37 | H20: 0.1 | I20: 85.13 | J20: 85.13 | K20: 88.75 | L20: =TRUE() -> TRUE | M20: 9 | N20: 28567 | O20: 262 | P20: 788 | Q20: 451 | R20: =IF(Q20=0,999,O20/(Q20/7)) -> 4.0665188 | S20: Standard | T20: 118399 | U20: 1291 | V20: 942.43 | W20: 31 | X20: 2639.03 | Y20: 0.73 | Z20: =IF(T20=0,0,U20/T20) -> 0.010903808 | AA20: =IF(X20=0,0,V20/X20) -> 0.35711227 | AB20: =IF(V20=0,0,X20/V20) -> 2.8002398
A21: SKU-1019 | B21: B0102603 | C21: Nimbus Home | D21: Nimbus Home Yoga Mat | E21: Fitness | F21: 18.84 | G21: 6.09 | H21: 0.1 | I21: 51.58 | J21: 48.14 | K21: 48.29 | L21: =FALSE() -> FALSE | M21: 5 | N21: 163506 | O21: 2821 | P21: 668 | Q21: 328 | R21: =IF(Q21=0,999,O21/(Q21/7)) -> 60.204268 | S21: Standard | T21: 53243 | U21: 660 | V21: 778.8 | W21: 82 | X21: 4229.56 | Y21: 1.18 | Z21: =IF(T21=0,0,U21/T21) -> 0.012395996 | AA21: =IF(X21=0,0,V21/X21) -> 0.18413263 | AB21: =IF(V21=0,0,X21/V21) -> 5.430868
A22: SKU-1020 | B22: B0102740 | C22: TrailForge | D22: TrailForge Exercise Ball | E22: Fitness | F22: 24.55 | G22: 11.42 | H22: 0.12 | I22: 64.18 | J22: 64.18 | K22: 61.59 | L22: =TRUE() -> TRUE | M22: 6 | N22: 75362 | O22: 1870 | P22: 1383 | Q22: 222 | R22: =IF(Q22=0,999,O22/(Q22/7)) -> 58.963964 | S22: Oversize | T22: 28510 | U22: 288 | V22: 443.52 | W22: 16 | X22: 1026.88 | Y22: 1.54 | Z22: =IF(T22=0,0,U22/T22) -> 0.010101719 | AA22: =IF(X22=0,0,V22/X22) -> 0.43191025 | AB22: =IF(V22=0,0,X22/V22) -> 2.3152958
A23: SKU-1021 | B23: B0102877 | C23: TrailForge | D23: TrailForge Adjustable Dumbbells | E23: Fitness | F23: 17 | G23: 11.81 | H23: 0.12 | I23: 62.7 | J23: 61.88 | K23: 63.56 | L23: =FALSE() -> FALSE | M23: 1 | N23: 59038 | O23: 87 | P23: 932 | Q23: 210 | R23: =IF(Q23=0,999,O23/(Q23/7)) -> 2.9 | S23: Oversize | T23: 54821 | U23: 800 | V23: 968 | W23: 43 | X23: 2696.1 | Y23: 1.21 | Z23: =IF(T23=0,0,U23/T23) -> 0.014592948 | AA23: =IF(X23=0,0,V23/X23) -> 0.35903713 | AB23: =IF(V23=0,0,X23/V23) -> 2.7852273
A24: SKU-1022 | B24: B0103014 | C24: TrailForge | D24: TrailForge Exercise Ball | E24: Fitness | F24: 13.07 | G24: 11.75 | H24: 0.08 | I24: 49.54 | J24: 49.1 | K24: 50.63 | L24: =FALSE() -> FALSE | M24: 12 | N24: 57517 | O24: 182 | P24: 934 | Q24: 187 | R24: =IF(Q24=0,999,O24/(Q24/7)) -> 6.8128342 | S24: Oversize | T24: 17977 | U24: 244 | V24: 329.4 | W24: 15 | X24: 743.1 | Y24: 1.35 | Z24: =IF(T24=0,0,U24/T24) -> 0.013572899 | AA24: =IF(X24=0,0,V24/X24) -> 0.44327816 | AB24: =IF(V24=0,0,X24/V24) -> 2.2559199
A25: SKU-1023 | B25: B0103151 | C25: TrailForge | D25: TrailForge Massage Gun | E25: Fitness | F25: 12.59 | G25: 4.99 | H25: 0.15 | I25: 35.37 | J25: 35.37 | K25: 33.22 | L25: =TRUE() -> TRUE | M25: 8 | N25: 124583 | O25: 4535 | P25: 1283 | Q25: 467 | R25: =IF(Q25=0,999,O25/(Q25/7)) -> 67.976445 | S25: Standard | T25: 31858 | U25: 233 | V25: 109.51 | W25: 14 | X25: 495.18 | Y25: 0.47 | Z25: =IF(T25=0,0,U25/T25) -> 0.0073137046 | AA25: =IF(X25=0,0,V25/X25) -> 0.2211519 | AB25: =IF(V25=0,0,X25/V25) -> 4.5217788
A26: SKU-1024 | B26: B0103288 | C26: TrailForge | D26: TrailForge Jump Rope | E26: Fitness | F26: 14.03 | G26: 3.36 | H26: 0.1 | I26: 36.86 | J26: 36.86 | K26: 34.15 | L26: =TRUE() -> TRUE | M26: 3 | N26: 56236 | O26: 482 | P26: 797 | Q26: 72 | R26: =IF(Q26=0,999,O26/(Q26/7)) -> 46.861111 | S26: Standard | T26: 119098 | U26: 1572 | V26: 2782.44 | W26: 597 | X26: 22005.42 | Y26: 1.77 | Z26: =IF(T26=0,0,U26/T26) -> 0.013199214 | AA26: =IF(X26=0,0,V26/X26) -> 0.12644339 | AB26: =IF(V26=0,0,X26/V26) -> 7.9086773
A27: SKU-1025 | B27: B0103425 | C27: TrailForge | D27: TrailForge Massage Gun | E27: Fitness | F27: 8.94 | G27: 4.58 | H27: 0.15 | I27: 40.42 | J27: 38.4 | K27: 38.71 | L27: =FALSE() -> FALSE | M27: 6 | N27: 57962 | O27: 3982 | P27: 1483 | Q27: 506 | R27: =IF(Q27=0,999,O27/(Q27/7)) -> 55.086957 | S27: Standard | T27: 22132 | U27: 312 | V27: 539.76 | W27: 30 | X27: 1212.6 | Y27: 1.73 | Z27: =IF(T27=0,0,U27/T27) -> 0.014097235 | AA27: =IF(X27=0,0,V27/X27) -> 0.44512618 | AB27: =IF(V27=0,0,X27/V27) -> 2.246554
A28: SKU-1026 | B28: B0103562 | C28: TrailForge | D28: TrailForge Floating Shelf | E28: Home Decor | F28: 3.53 | G28: 5.54 | H28: 0.08 | I28: 12.15 | J28: 12.15 | K28: 11.89 | L28: =TRUE() -> TRUE | M28: 1 | N28: 121181 | O28: 1511 | P28: 569 | Q28: 193 | R28: =IF(Q28=0,999,O28/(Q28/7)) -> 54.803109 | S28: Standard | T28: 99067 | U28: 1526 | V28: 1495.48 | W28: 311 | X28: 3778.65 | Y28: 0.98 | Z28: =IF(T28=0,0,U28/T28) -> 0.015403717 | AA28: =IF(X28=0,0,V28/X28) -> 0.39577098 | AB28: =IF(V28=0,0,X28/V28) -> 2.5267138
A29: SKU-1027 | B29: B0103699 | C29: TrailForge | D29: TrailForge Decorative Vase | E29: Home Decor | F29: 3.66 | G29: 7.5 | H29: 0.12 | I29: 11.54 | J29: 11.15 | K29: 11.31 | L29: =FALSE() -> FALSE | M29: 3 | N29: 8284 | O29: 119 | P29: 1155 | Q29: 260 | R29: =IF(Q29=0,999,O29/(Q29/7)) -> 3.2038462 | S29: Standard | T29: 29069 | U29: 279 | V29: 203.67 | W29: 73 | X29: 842.42 | Y29: 0.73 | Z29: =IF(T29=0,0,U29/T29) -> 0.0095978534 | AA29: =IF(X29=0,0,V29/X29) -> 0.24176776 | AB29: =IF(V29=0,0,X29/V29) -> 4.1362007
A30: SKU-1028 | B30: B0103836 | C30: TrailForge | D30: TrailForge Table Runner | E30: Home Decor | F30: 20.77 | G30: 3.52 | H30: 0.1 | I30: 58.57 | J30: 58.57 | K30: 51.05 | L30: =TRUE() -> TRUE | M30: 4 | N30: 81927 | O30: 516 | P30: 1212 | Q30: 596 | R30: =IF(Q30=0,999,O30/(Q30/7)) -> 6.0604027 | S30: Standard | T30: 91020 | U30: 1274 | V30: 904.54 | W30: 44 | X30: 2577.08 | Y30: 0.71 | Z30: =IF(T30=0,0,U30/T30) -> 0.013996924 | AA30: =IF(X30=0,0,V30/X30) -> 0.35099415 | AB30: =IF(V30=0,0,X30/V30) -> 2.8490503
A31: SKU-1029 | B31: B0103973 | C31: TrailForge | D31: TrailForge Scented Candle Trio | E31: Home Decor | F31: 25.59 | G31: 3.54 | H31: 0.08 | I31: 78.01 | J31: 71.84 | K31: 74.62 | L31: =FALSE() -> FALSE | M31: 5 | N31: 169899 | O31: 1640 | P31: 1301 | Q31: 356 | R31: =IF(Q31=0,999,O31/(Q31/7)) -> 32.247191 | S31: Standard | T31: 117360 | U31: 1631 | V31: 2299.71 | W31: 112 | X31: 8737.12 | Y31: 1.41 | Z31: =IF(T31=0,0,U31/T31) -> 0.01389741 | AA31: =IF(X31=0,0,V31/X31) -> 0.26321145 | AB31: =IF(V31=0,0,X31/V31) -> 3.7992269
A32: SKU-1030 | B32: B0104110 | C32: PureCove | D32: PureCove Sleeping Bag | E32: Outdoor | F32: 23.43 | G32: 6.64 | H32: 0.15 | I32: 87.23 | J32: 79.35 | K32: 81.74 | L32: =FALSE() -> FALSE | M32: 7 | N32: 64505 | O32: 843 | P32: 688 | Q32: 95 | R32: =IF(Q32=0,999,O32/(Q32/7)) -> 62.115789 | S32: Standard | T32: 4261 | U32: 42 | V32: 35.28 | W32: 1 | X32: 87.23 | Y32: 0.84 | Z32: =IF(T32=0,0,U32/T32) -> 0.0098568411 | AA32: =IF(X32=0,0,V32/X32) -> 0.40444801 | AB32: =IF(V32=0,0,X32/V32) -> 2.4725057
A33: SKU-1031 | B33: B0104247 | C33: PureCove | D33: PureCove Headlamp | E33: Outdoor | F33: 20.76 | G33: 6.96 | H33: 0.12 | I33: 73.82 | J33: 60.6 | K33: 62.9 | L33: =FALSE() -> FALSE | M33: 8 | N33: 106692 | O33: 4806 | P33: 35 | Q33: 507 | R33: =IF(Q33=0,999,O33/(Q33/7)) -> 66.35503 | S33: Standard | T33: 12696 | U33: 95 | V33: 91.2 | W33: 6 | X33: 442.92 | Y33: 0.96 | Z33: =IF(T33=0,0,U33/T33) -> 0.0074826717 | AA33: =IF(X33=0,0,V33/X33) -> 0.20590626 | AB33: =IF(V33=0,0,X33/V33) -> 4.8565789
A34: SKU-1032 | B34: B0104384 | C34: PureCove | D34: PureCove Portable Stove | E34: Outdoor | F34: 12.63 | G34: 4.55 | H34: 0.12 | I34: 39.51 | J34: 39.51 | K34: 39.14 | L34: =TRUE() -> TRUE | M34: 5 | N34: 66053 | O34: 358 | P34: 392 | Q34: 243 | R34: =IF(Q34=0,999,O34/(Q34/7)) -> 10.312757 | S34: Standard | T34: 28861 | U34: 372 | V34: 282.72 | W34: 23 | X34: 908.73 | Y34: 0.76 | Z34: =IF(T34=0,0,U34/T34) -> 0.012889366 | AA34: =IF(X34=0,0,V34/X34) -> 0.31111551 | AB34: =IF(V34=0,0,X34/V34) -> 3.2142402
A35: SKU-1033 | B35: B0104521 | C35: PureCove | D35: PureCove Sleeping Bag | E35: Outdoor | F35: 22.89 | G35: 6.75 | H35: 0.12 | I35: 57.73 | J35: 57.73 | K35: 53.24 | L35: =TRUE() -> TRUE | M35: 3 | N35: 140170 | O35: 383 | P35: 1306 | Q35: 136 | R35: =IF(Q35=0,999,O35/(Q35/7)) -> 19.713235 | S35: Standard | T35: 114330 | U35: 1486 | V35: 743 | W35: 104 | X35: 6003.92 | Y35: 0.5 | Z35: =IF(T35=0,0,U35/T35) -> 0.012997463 | AA35: =IF(X35=0,0,V35/X35) -> 0.12375248 | AB35: =IF(V35=0,0,X35/V35) -> 8.080646
A36: SKU-1034 | B36: B0104658 | C36: PureCove | D36: PureCove Hammock | E36: Outdoor | F36: 14.23 | G36: 7.97 | H36: 0.08 | I36: 47.54 | J36: 47.54 | K36: 49.36 | L36: =TRUE() -> TRUE | M36: 4 | N36: 17279 | O36: 2214 | P36: 174 | Q36: 417 | R36: =IF(Q36=0,999,O36/(Q36/7)) -> 37.165468 | S36: Oversize | T36: 33030 | U36: 178 | V36: 267 | W36: 18 | X36: 855.72 | Y36: 1.5 | Z36: =IF(T36=0,0,U36/T36) -> 0.0053890403 | AA36: =IF(X36=0,0,V36/X36) -> 0.31201795 | AB36: =IF(V36=0,0,X36/V36) -> 3.2049438
A37: SKU-1035 | B37: B0104795 | C37: PureCove | D37: PureCove Portable Stove | E37: Outdoor | F37: 8.81 | G37: 5.03 | H37: 0.15 | I37: 28.04 | J37: 27.26 | K37: 28.66 | L37: =FALSE() -> FALSE | M37: 4 | N37: 162948 | O37: 164 | P37: 541 | Q37: 68 | R37: =IF(Q37=0,999,O37/(Q37/7)) -> 16.882353 | S37: Standard | T37: 87063 | U37: 435 | V37: 308.85 | W37: 36 | X37: 1009.44 | Y37: 0.71 | Z37: =IF(T37=0,0,U37/T37) -> 0.0049963819 | AA37: =IF(X37=0,0,V37/X37) -> 0.30596172 | AB37: =IF(V37=0,0,X37/V37) -> 3.2683827
A38: SKU-1036 | B38: B0104932 | C38: PureCove | D38: PureCove Travel Pillow | E38: Travel | F38: 3.07 | G38: 5.67 | H38: 0.12 | I38: 10.2 | J38: 10.2 | K38: 10.2 | L38: =TRUE() -> TRUE | M38: 0 | N38: 74262 | O38: 727 | P38: 870 | Q38: 471 | R38: =IF(Q38=0,999,O38/(Q38/7)) -> 10.804671 | S38: Standard | T38: 15543 | U38: 163 | V38: 215.16 | W38: 50 | X38: 510 | Y38: 1.32 | Z38: =IF(T38=0,0,U38/T38) -> 0.010487036 | AA38: =IF(X38=0,0,V38/X38) -> 0.42188235 | AB38: =IF(V38=0,0,X38/V38) -> 2.3703291
A39: SKU-1037 | B39: B0105069 | C39: PureCove | D39: PureCove Travel Pillow | E39: Travel | F39: 3.92 | G39: 4.38 | H39: 0.12 | I39: 15.7 | J39: 13.57 | K39: 13.74 | L39: =FALSE() -> FALSE | M39: 7 | N39: 71517 | O39: 2591 | P39: 1236 | Q39: 519 | R39: =IF(Q39=0,999,O39/(Q39/7)) -> 34.94605 | S39: Standard | T39: 33316 | U39: 143 | V39: 98.67 | W39: 18 | X39: 282.6 | Y39: 0.69 | Z39: =IF(T39=0,0,U39/T39) -> 0.004292232 | AA39: =IF(X39=0,0,V39/X39) -> 0.34915074 | AB39: =IF(V39=0,0,X39/V39) -> 2.8640924
A40: SKU-1038 | B40: B0105206 | C40: PureCove | D40: PureCove Luggage Scale | E40: Travel | F40: 12.74 | G40: 6.44 | H40: 0.12 | I40: 56.96 | J40: 47.83 | K40: 48.87 | L40: =FALSE() -> FALSE | M40: 9 | N40: 170939 | O40: 4199 | P40: 186 | Q40: 459 | R40: =IF(Q40=0,999,O40/(Q40/7)) -> 64.037037 | S40: Standard | T40: 62105 | U40: 509 | V40: 432.65 | W40: 22 | X40: 1253.12 | Y40: 0.85 | Z40: =IF(T40=0,0,U40/T40) -> 0.0081957974 | AA40: =IF(X40=0,0,V40/X40) -> 0.34525824 | AB40: =IF(V40=0,0,X40/V40) -> 2.8963828
...

Sheet Brand Summary
A1: Brand | B1: Products | C1: Total Ad Spend ($) | D1: Total Ad Sales ($) | E1: Blended ACOS | F1: Avg Days of Supply | G1: Buy Box Win Rate | H1: Avg Current Price ($)
A2: Aerovo | B2: =COUNTIF('Master SKU Data'!C:C,A2) -> 10 | C2: =SUMIF('Master SKU Data'!C:C,A2,'Master SKU Data'!V:V) -> 9608.51 | D2: =SUMIF('Master SKU Data'!C:C,A2,'Master SKU Data'!X:X) -> 43575.63 | E2: =IF(D2=0,0,C2/D2) -> 0.22050192 | F2: =AVERAGEIF('Master SKU Data'!C:C,A2,'Master SKU Data'!R:R) -> 25.501535 | G2: =AVERAGEIF('Master SKU Data'!C:C,A2,'Master SKU Data'!L:L) -> 0.6 | H2: =AVERAGEIF('Master SKU Data'!C:C,A2,'Master SKU Data'!I:I) -> 47.613
A3: Nimbus Home | B3: =COUNTIF('Master SKU Data'!C:C,A3) -> 10 | C3: =SUMIF('Master SKU Data'!C:C,A3,'Master SKU Data'!V:V) -> 10373.18 | D3: =SUMIF('Master SKU Data'!C:C,A3,'Master SKU Data'!X:X) -> 50602.12 | E3: =IF(D3=0,0,C3/D3) -> 0.20499497 | F3: =AVERAGEIF('Master SKU Data'!C:C,A3,'Master SKU Data'!R:R) -> 27.198291 | G3: =AVERAGEIF('Master SKU Data'!C:C,A3,'Master SKU Data'!L:L) -> 0.6 | H3: =AVERAGEIF('Master SKU Data'!C:C,A3,'Master SKU Data'!I:I) -> 51.501
A4: TrailForge | B4: =COUNTIF('Master SKU Data'!C:C,A4) -> 10 | C4: =SUMIF('Master SKU Data'!C:C,A4,'Master SKU Data'!V:V) -> 10076.03 | D4: =SUMIF('Master SKU Data'!C:C,A4,'Master SKU Data'!X:X) -> 44114.55 | E4: =IF(D4=0,0,C4/D4) -> 0.22840605 | F4: =AVERAGEIF('Master SKU Data'!C:C,A4,'Master SKU Data'!R:R) -> 33.491586 | G4: =AVERAGEIF('Master SKU Data'!C:C,A4,'Master SKU Data'!L:L) -> 0.5 | H4: =AVERAGEIF('Master SKU Data'!C:C,A4,'Master SKU Data'!I:I) -> 44.934
A5: PureCove | B5: =COUNTIF('Master SKU Data'!C:C,A5) -> 10 | C5: =SUMIF('Master SKU Data'!C:C,A5,'Master SKU Data'!V:V) -> 3640.47 | D5: =SUMIF('Master SKU Data'!C:C,A5,'Master SKU Data'!X:X) -> 17754.8 | E5: =IF(D5=0,0,C5/D5) -> 0.20504145 | F5: =AVERAGEIF('Master SKU Data'!C:C,A5,'Master SKU Data'!R:R) -> 32.626824 | G5: =AVERAGEIF('Master SKU Data'!C:C,A5,'Master SKU Data'!L:L) -> 0.5 | H5: =AVERAGEIF('Master SKU Data'!C:C,A5,'Master SKU Data'!I:I) -> 45.31
A6: Brightway | B6: =COUNTIF('Master SKU Data'!C:C,A6) -> 10 | C6: =SUMIF('Master SKU Data'!C:C,A6,'Master SKU Data'!V:V) -> 5102.28 | D6: =SUMIF('Master SKU Data'!C:C,A6,'Master SKU Data'!X:X) -> 19599.33 | E6: =IF(D6=0,0,C6/D6) -> 0.26032931 | F6: =AVERAGEIF('Master SKU Data'!C:C,A6,'Master SKU Data'!R:R) -> 26.750233 | G6: =AVERAGEIF('Master SKU Data'!C:C,A6,'Master SKU Data'!L:L) -> 0.8 | H6: =AVERAGEIF('Master SKU Data'!C:C,A6,'Master SKU Data'!I:I) -> 62.85
A7: UrbanCraft | B7: =COUNTIF('Master SKU Data'!C:C,A7) -> 10 | C7: =SUMIF('Master SKU Data'!C:C,A7,'Master SKU Data'!V:V) -> 3685.38 | D7: =SUMIF('Master SKU Data'!C:C,A7,'Master SKU Data'!X:X) -> 12689.21 | E7: =IF(D7=0,0,C7/D7) -> 0.29043416 | F7: =AVERAGEIF('Master SKU Data'!C:C,A7,'Master SKU Data'!R:R) -> 26.542906 | G7: =AVERAGEIF('Master SKU Data'!C:C,A7,'Master SKU Data'!L:L) -> 0.8 | H7: =AVERAGEIF('Master SKU Data'!C:C,A7,'Master SKU Data'!I:I) -> 50.028
A8: VitalPeak | B8: =COUNTIF('Master SKU Data'!C:C,A8) -> 10 | C8: =SUMIF('Master SKU Data'!C:C,A8,'Master SKU Data'!V:V) -> 5131.17 | D8: =SUMIF('Master SKU Data'!C:C,A8,'Master SKU Data'!X:X) -> 18802.05 | E8: =IF(D8=0,0,C8/D8) -> 0.27290482 | F8: =AVERAGEIF('Master SKU Data'!C:C,A8,'Master SKU Data'!R:R) -> 37.166327 | G8: =AVERAGEIF('Master SKU Data'!C:C,A8,'Master SKU Data'!L:L) -> 0.7 | H8: =AVERAGEIF('Master SKU Data'!C:C,A8,'Master SKU Data'!I:I) -> 50.861
A9: Cozynest | B9: =COUNTIF('Master SKU Data'!C:C,A9) -> 10 | C9: =SUMIF('Master SKU Data'!C:C,A9,'Master SKU Data'!V:V) -> 6567.44 | D9: =SUMIF('Master SKU Data'!C:C,A9,'Master SKU Data'!X:X) -> 26983.31 | E9: =IF(D9=0,0,C9/D9) -> 0.24338897 | F9: =AVERAGEIF('Master SKU Data'!C:C,A9,'Master SKU Data'!R:R) -> 39.138114 | G9: =AVERAGEIF('Master SKU Data'!C:C,A9,'Master SKU Data'!L:L) -> 0.8 | H9: =AVERAGEIF('Master SKU Data'!C:C,A9,'Master SKU Data'!I:I) -> 66.973
A10: Solstice Gear | B10: =COUNTIF('Master SKU Data'!C:C,A10) -> 10 | C10: =SUMIF('Master SKU Data'!C:C,A10,'Master SKU Data'!V:V) -> 5287.45 | D10: =SUMIF('Master SKU Data'!C:C,A10,'Master SKU Data'!X:X) -> 22502.51 | E10: =IF(D10=0,0,C10/D10) -> 0.23497157 | F10: =AVERAGEIF('Master SKU Data'!C:C,A10,'Master SKU Data'!R:R) -> 21.142748 | G10: =AVERAGEIF('Master SKU Data'!C:C,A10,'Master SKU Data'!L:L) -> 0.6 | H10: =AVERAGEIF('Master SKU Data'!C:C,A10,'Master SKU Data'!I:I) -> 46.865
A11: EverGlow | B11: =COUNTIF('Master SKU Data'!C:C,A11) -> 10 | C11: =SUMIF('Master SKU Data'!C:C,A11,'Master SKU Data'!V:V) -> 8741.44 | D11: =SUMIF('Master SKU Data'!C:C,A11,'Master SKU Data'!X:X) -> 32691.49 | E11: =IF(D11=0,0,C11/D11) -> 0.26739191 | F11: =AVERAGEIF('Master SKU Data'!C:C,A11,'Master SKU Data'!R:R) -> 21.236426 | G11: =AVERAGEIF('Master SKU Data'!C:C,A11,'Master SKU Data'!L:L) -> 0.8 | H11: =AVERAGEIF('Master SKU Data'!C:C,A11,'Master SKU Data'!I:I) -> 58.081
A12: TOTAL / BLENDED | B12: =SUM(B2:B11) -> 100 | C12: =SUM(C2:C11) -> 68213.35 | D12: =SUM(D2:D11) -> 289315 | E12: =IF(D12=0,0,C12/D12) -> 0.23577537 | F12: =AVERAGE('Master SKU Data'!R2:R101) -> 29.079499 | G12: =AVERAGE('Master SKU Data'!L2:L101) -> 0.67 | H12: =AVERAGE('Master SKU Data'!I2:I101) -> 52.5016
